<?xml version="1.0" ?>
<sdf version="1.9">
  <world name="lunabotics_field">
    
    <!-- Physics settings -->
    <physics name="1ms" type="ignored">
      <max_step_size>0.001</max_step_size>
      <real_time_factor>1.0</real_time_factor>
    </physics>

    <plugin
      filename="gz-sim-physics-system"
      name="gz::sim::systems::Physics">
    </plugin>
    <plugin
      filename="gz-sim-user-commands-system"
      name="gz::sim::systems::UserCommands">
    </plugin>
    <plugin
      filename="gz-sim-scene-broadcaster-system"
      name="gz::sim::systems::SceneBroadcaster">
    </plugin>
    <plugin
      filename="gz-sim-sensors-system"
      name="gz::sim::systems::Sensors">
      <render_engine>ogre2</render_engine>
    </plugin>

    <!-- Lighting -->
    <light type="directional" name="sun">
      <cast_shadows>true</cast_shadows>
      <pose>0 0 10 0 0 0</pose>
      <diffuse>0.8 0.8 0.8 1</diffuse>
      <specular>0.2 0.2 0.2 1</specular>
      <attenuation>
        <range>1000</range>
        <constant>0.9</constant>
        <linear>0.01</linear>
        <quadratic>0.001</quadratic>
      </attenuation>
      <direction>-0.5 0.1 -0.9</direction>
    </light>

    <!-- Ground plane (Terrain) -->
    <model name="terrain">
      <static>true</static>
      <link name="terrain_link">
        <pose>0 0 0.15 0 0 0</pose>
        <collision name="terrain_collision">
          <geometry>
            <box>
              <size>6.8 5.0 0.3</size>
            </box>
          </geometry>
        </collision>
        <visual name="terrain_visual">
          <geometry>
            <box>
              <size>6.8 5.0 0.3</size>
            </box>
          </geometry>
          <material>
            <ambient>0.55 0.52 0.47 1</ambient>
            <diffuse>0.55 0.52 0.47 1</diffuse>
          </material>
        </visual>
      </link>
    </model>

    <!-- North Wall -->
    <model name="north_wall">
      <static>true</static>
      <link name="north_wall_link">
        <pose>0 2.5 0.25 0 0 0</pose>
        <collision name="north_wall_collision">
          <geometry>
            <box>
              <size>6.8 0.1 0.5</size>
            </box>
          </geometry>
        </collision>
        <visual name="north_wall_visual">
          <geometry>
            <box>
              <size>6.8 0.1 0.5</size>
            </box>
          </geometry>
          <material>
            <ambient>0.7 0.7 0.7 1</ambient>
            <diffuse>0.7 0.7 0.7 1</diffuse>
          </material>
        </visual>
      </link>
    </model>

    <!-- South Wall -->
    <model name="south_wall">
      <static>true</static>
      <link name="south_wall_link">
        <pose>0 -2.5 0.25 0 0 0</pose>
        <collision name="south_wall_collision">
          <geometry>
            <box>
              <size>6.8 0.1 0.5</size>
            </box>
          </geometry>
        </collision>
        <visual name="south_wall_visual">
          <geometry>
            <box>
              <size>6.8 0.1 0.5</size>
            </box>
          </geometry>
          <material>
            <ambient>0.7 0.7 0.7 1</ambient>
            <diffuse>0.7 0.7 0.7 1</diffuse>
          </material>
        </visual>
      </link>
    </model>

    <!-- East Wall -->
    <model name="east_wall">
      <static>true</static>
      <link name="east_wall_link">
        <pose>3.4 0 0.25 0 0 0</pose>
        <collision name="east_wall_collision">
          <geometry>
            <box>
              <size>0.1 5.0 0.5</size>
            </box>
          </geometry>
        </collision>
        <visual name="east_wall_visual">
          <geometry>
            <box>
              <size>0.1 5.0 0.5</size>
            </box>
          </geometry>
          <material>
            <ambient>0.7 0.7 0.7 1</ambient>
            <diffuse>0.7 0.7 0.7 1</diffuse>
          </material>
        </visual>
      </link>
    </model>

    <!-- West Wall -->
    <model name="west_wall">
      <static>true</static>
      <link name="west_wall_link">
        <pose>-3.4 0 0.25 0 0 0</pose>
        <collision name="west_wall_collision">
          <geometry>
            <box>
              <size>0.1 5.0 0.5</size>
            </box>
          </geometry>
        </collision>
        <visual name="west_wall_visual">
          <geometry>
            <box>
              <size>0.1 5.0 0.5</size>
            </box>
          </geometry>
          <material>
            <ambient>0.7 0.7 0.7 1</ambient>
            <diffuse>0.7 0.7 0.7 1</diffuse>
          </material>
        </visual>
      </link>
    </model>

    <!-- Start Zone (green marker) -->
    <model name="start_zone">
      <static>true</static>
      <link name="start_zone_link">
        <pose>-2.9 -1.9 0.31 0 0 0</pose>
        <visual name="start_zone_visual">
          <geometry>
            <box>
              <size>2.0 1.0 0.02</size>
            </box>
          </geometry>
          <material>
            <ambient>0.1 0.8 0.1 0.6</ambient>
            <diffuse>0.1 0.8 0.1 0.6</diffuse>
          </material>
        </visual>
      </link>
    </model>

    <!-- Brim Pad (yellow marker) -->
    <model name="brim_pad">
      <static>true</static>
      <link name="brim_pad_link">
        <pose>2.4 1.8 0.31 0 0 0</pose>
        <visual name="brim_pad_visual">
          <geometry>
            <box>
              <size>1.0 1.5 0.02</size>
            </box>
          </geometry>
          <material>
            <ambient>0.9 0.8 0.1 0.6</ambient>
            <diffuse>0.9 0.8 0.1 0.6</diffuse>
          </material>
        </visual>
      </link>
    </model>

    <!-- Brim Poles -->
    <model name="pole_ne">
      <static>true</static>
      <link name="pole_ne_link">
        <pose>2.9 2.55 0.6 0 0 0</pose>
        <collision name="pole_ne_collision">
          <geometry>
            <cylinder>
              <radius>0.03</radius>
              <length>1.2</length>
            </cylinder>
          </geometry>
        </collision>
        <visual name="pole_ne_visual">
          <geometry>
            <cylinder>
              <radius>0.03</radius>
              <length>1.2</length>
            </cylinder>
          </geometry>
          <material>
            <ambient>0.9 0.1 0.1 1</ambient>
            <diffuse>0.9 0.1 0.1 1</diffuse>
          </material>
        </visual>
      </link>
    </model>

    <model name="pole_nw">
      <static>true</static>
      <link name="pole_nw_link">
        <pose>1.9 2.55 0.6 0 0 0</pose>
        <collision name="pole_nw_collision">
          <geometry>
            <cylinder>
              <radius>0.03</radius>
              <length>1.2</length>
            </cylinder>
          </geometry>
        </collision>
        <visual name="pole_nw_visual">
          <geometry>
            <cylinder>
              <radius>0.03</radius>
              <length>1.2</length>
            </cylinder>
          </geometry>
          <material>
            <ambient>0.9 0.1 0.1 1</ambient>
            <diffuse>0.9 0.1 0.1 1</diffuse>
          </material>
        </visual>
      </link>
    </model>

    <model name="pole_se">
      <static>true</static>
      <link name="pole_se_link">
        <pose>2.9 1.05 0.6 0 0 0</pose>
        <collision name="pole_se_collision">
          <geometry>
            <cylinder>
              <radius>0.03</radius>
              <length>1.2</length>
            </cylinder>
          </geometry>
        </collision>
        <visual name="pole_se_visual">
          <geometry>
            <cylinder>
              <radius>0.03</radius>
              <length>1.2</length>
            </cylinder>
          </geometry>
          <material>
            <ambient>0.9 0.1 0.1 1</ambient>
            <diffuse>0.9 0.1 0.1 1</diffuse>
          </material>
        </visual>
      </link>
    </model>

    <model name="pole_sw">
      <static>true</static>
      <link name="pole_sw_link">
        <pose>1.9 1.05 0.6 0 0 0</pose>
        <collision name="pole_sw_collision">
          <geometry>
            <cylinder>
              <radius>0.03</radius>
              <length>1.2</length>
            </cylinder>
          </geometry>
        </collision>
        <visual name="pole_sw_visual">
          <geometry>
            <cylinder>
              <radius>0.03</radius>
              <length>1.2</length>
            </cylinder>
          </geometry>
          <material>
            <ambient>0.9 0.1 0.1 1</ambient>
            <diffuse>0.9 0.1 0.1 1</diffuse>
          </material>
        </visual>
      </link>
    </model>

    <!-- Rocks -->
    <model name="rock_1">
      <pose>-0.8 1.2 0.3 0 0 0</pose>
      <link name="rock_1_link">
        <inertial>
          <mass>10</mass>
          <inertia>
            <ixx>0.09</ixx>
            <iyy>0.09</iyy>
            <izz>0.09</izz>
          </inertia>
        </inertial>
        <collision name="rock_1_collision">
          <geometry>
            <sphere>
              <radius>0.15</radius>
            </sphere>
          </geometry>
        </collision>
        <visual name="rock_1_visual">
          <geometry>
            <sphere>
              <radius>0.15</radius>
            </sphere>
          </geometry>
          <material>
            <ambient>0.4 0.4 0.4 1</ambient>
            <diffuse>0.4 0.4 0.4 1</diffuse>
          </material>
        </visual>
      </link>
    </model>

    <model name="rock_2">
      <pose>1.1 -0.6 0.33 0 0 0</pose>
      <link name="rock_2_link">
        <inertial>
          <mass>15</mass>
          <inertia>
            <ixx>0.15</ixx>
            <iyy>0.15</iyy>
            <izz>0.15</izz>
          </inertia>
        </inertial>
        <collision name="rock_2_collision">
          <geometry>
            <sphere>
              <radius>0.18</radius>
            </sphere>
          </geometry>
        </collision>
        <visual name="rock_2_visual">
          <geometry>
            <sphere>
              <radius>0.18</radius>
            </sphere>
          </geometry>
          <material>
            <ambient>0.45 0.45 0.45 1</ambient>
            <diffuse>0.45 0.45 0.45 1</diffuse>
          </material>
        </visual>
      </link>
    </model>

    <model name="rock_3">
      <pose>-2.0 0.3 0.35 0 0 0</pose>
      <link name="rock_3_link">
        <inertial>
          <mass>20</mass>
          <inertia>
            <ixx>0.2</ixx>
            <iyy>0.2</iyy>
            <izz>0.2</izz>
          </inertia>
        </inertial>
        <collision name="rock_3_collision">
          <geometry>
            <sphere>
              <radius>0.20</radius>
            </sphere>
          </geometry>
        </collision>
        <visual name="rock_3_visual">
          <geometry>
            <sphere>
              <radius>0.20</radius>
            </sphere>
          </geometry>
          <material>
            <ambient>0.35 0.35 0.35 1</ambient>
            <diffuse>0.35 0.35 0.35 1</diffuse>
          </material>
        </visual>
      </link>
    </model>

    <!-- DUMMY ROVER (1m x 0.75m x 0.35m) -->
    <model name="lunabotics_rover">
      <pose>-2.9 -1.9 0.48 0 0 1.5708</pose>
      
      <link name="chassis">
        <inertial>
          <mass>50</mass>
          <inertia>
            <ixx>3.646</ixx>
            <iyy>5.208</iyy>
            <izz>8.333</izz>
          </inertia>
        </inertial>

        <!-- Chassis collision and visual -->
        <collision name="chassis_collision">
          <geometry>
            <box>
              <size>1.0 0.75 0.35</size>
            </box>
          </geometry>
        </collision>
        <visual name="chassis_visual">
          <geometry>
            <box>
              <size>1.0 0.75 0.35</size>
            </box>
          </geometry>
          <material>
            <ambient>0.2 0.3 0.9 1</ambient>
            <diffuse>0.2 0.3 0.9 1</diffuse>
          </material>
        </visual>

        <!-- RGB Camera (left side) -->
        <sensor name="rgb_camera" type="camera">
          <pose>0 0.4 0.2 0 0 1.5708</pose>
          <camera>
            <horizontal_fov>1.2</horizontal_fov>
            <image>
              <width>1920</width>
              <height>1080</height>
            </image>
            <clip>
              <near>0.1</near>
              <far>100</far>
            </clip>
          </camera>
          <always_on>1</always_on>
          <update_rate>30</update_rate>
          <visualize>true</visualize>
        </sensor>

        <!-- LiDAR (top center) -->
        <sensor name="lidar" type="gpu_lidar">
          <pose>0 0 0.25 0 0 0</pose>
          <topic>lidar</topic>
          <gz_frame_id>lidar_frame</gz_frame_id>
          <update_rate>10</update_rate>
          <lidar>
            <scan>
              <horizontal>
                <samples>512</samples>
                <resolution>1</resolution>
                <min_angle>-3.14159</min_angle>
                <max_angle>3.14159</max_angle>
              </horizontal>
              <vertical>
                <samples>16</samples>
                <resolution>1</resolution>
                <min_angle>-0.2</min_angle>
                <max_angle>0.2</max_angle>
              </vertical>
            </scan>
            <range>
              <min>0.15</min>
              <max>30</max>
              <resolution>0.01</resolution>
            </range>
            <noise>
              <type>gaussian</type>
              <mean>0.0</mean>
              <stddev>0.01</stddev>
            </noise>
          </lidar>
          <always_on>1</always_on>
          <visualize>true</visualize>
        </sensor>

        <!-- IR Sensor - Front -->
        <sensor name="ir_front" type="ray">
          <pose>0.52 0 0.1 0 0 0</pose>
          <ray>
            <scan>
              <horizontal>
                <samples>3</samples>
                <resolution>1</resolution>
                <min_angle>-0.1</min_angle>
                <max_angle>0.1</max_angle>
              </horizontal>
            </scan>
            <range>
              <min>0.05</min>
              <max>0.8</max>
              <resolution>0.01</resolution>
            </range>
          </ray>
          <always_on>1</always_on>
          <update_rate>20</update_rate>
          <visualize>true</visualize>
        </sensor>

        <!-- IR Sensor - Front Left Corner -->
        <sensor name="ir_front_left" type="ray">
          <pose>0.48 0.36 0.1 0 0 0.785</pose>
          <ray>
            <scan>
              <horizontal>
                <samples>3</samples>
                <resolution>1</resolution>
                <min_angle>-0.1</min_angle>
                <max_angle>0.1</max_angle>
              </horizontal>
            </scan>
            <range>
              <min>0.05</min>
              <max>0.8</max>
              <resolution>0.01</resolution>
            </range>
          </ray>
          <always_on>1</always_on>
          <update_rate>20</update_rate>
          <visualize>true</visualize>
        </sensor>

        <!-- IR Sensor - Front Right Corner -->
        <sensor name="ir_front_right" type="ray">
          <pose>0.48 -0.36 0.1 0 0 -0.785</pose>
          <ray>
            <scan>
              <horizontal>
                <samples>3</samples>
                <resolution>1</resolution>
                <min_angle>-0.1</min_angle>
                <max_angle>0.1</max_angle>
              </horizontal>
            </scan>
            <range>
              <min>0.05</min>
              <max>0.8</max>
              <resolution>0.01</resolution>
            </range>
          </ray>
          <always_on>1</always_on>
          <update_rate>20</update_rate>
          <visualize>true</visualize>
        </sensor>

        <!-- IR Sensor - Rear -->
        <sensor name="ir_rear" type="ray">
          <pose>-0.52 0 0.1 0 0 3.14159</pose>
          <ray>
            <scan>
              <horizontal>
                <samples>3</samples>
                <resolution>1</resolution>
                <min_angle>-0.1</min_angle>
                <max_angle>0.1</max_angle>
              </horizontal>
            </scan>
            <range>
              <min>0.05</min>
              <max>0.8</max>
              <resolution>0.01</resolution>
            </range>
          </ray>
          <always_on>1</always_on>
          <update_rate>20</update_rate>
          <visualize>true</visualize>
        </sensor>

        <!-- IR Sensor - Rear Left Corner -->
        <sensor name="ir_rear_left" type="ray">
          <pose>-0.48 0.36 0.1 0 0 2.356</pose>
          <ray>
            <scan>
              <horizontal>
                <samples>3</samples>
                <resolution>1</resolution>
                <min_angle>-0.1</min_angle>
                <max_angle>0.1</max_angle>
              </horizontal>
            </scan>
            <range>
              <min>0.05</min>
              <max>0.8</max>
              <resolution>0.01</resolution>
            </range>
          </ray>
          <always_on>1</always_on>
          <update_rate>20</update_rate>
          <visualize>true</visualize>
        </sensor>

        <!-- IR Sensor - Rear Right Corner -->
        <sensor name="ir_rear_right" type="ray">
          <pose>-0.48 -0.36 0.1 0 0 -2.356</pose>
          <ray>
            <scan>
              <horizontal>
                <samples>3</samples>
                <resolution>1</resolution>
                <min_angle>-0.1</min_angle>
                <max_angle>0.1</max_angle>
              </horizontal>
            </scan>
            <range>
              <min>0.05</min>
              <max>0.8</max>
              <resolution>0.01</resolution>
            </range>
          </ray>
          <always_on>1</always_on>
          <update_rate>20</update_rate>
          <visualize>true</visualize>
        </sensor>

        <!-- GPS/IMU plugin -->
        <sensor name="imu_sensor" type="imu">
          <always_on>1</always_on>
          <update_rate>100</update_rate>
        </sensor>

      </link>

      <!-- Front Left Wheel -->
      <link name="front_left_wheel">
        <pose>0.35 0.4 -0.15 -1.5708 0 0</pose>
        <inertial>
          <mass>2</mass>
          <inertia>
            <ixx>0.0225</ixx>
            <iyy>0.0225</iyy>
            <izz>0.045</izz>
          </inertia>
        </inertial>
        <collision name="front_left_wheel_collision">
          <geometry>
            <cylinder>
              <radius>0.15</radius>
              <length>0.08</length>
            </cylinder>
          </geometry>
          <surface>
            <friction>
              <ode>
                <mu>1.0</mu>
                <mu2>1.0</mu2>
              </ode>
            </friction>
          </surface>
        </collision>
        <visual name="front_left_wheel_visual">
          <geometry>
            <cylinder>
              <radius>0.15</radius>
              <length>0.08</length>
            </cylinder>
          </geometry>
          <material>
            <ambient>0.15 0.15 0.15 1</ambient>
            <diffuse>0.15 0.15 0.15 1</diffuse>
          </material>
        </visual>
      </link>

      <joint name="front_left_wheel_joint" type="revolute">
        <parent>chassis</parent>
        <child>front_left_wheel</child>
        <axis>
          <xyz>0 0 1</xyz>
          <limit>
            <lower>-1e9</lower>
            <upper>1e9</upper>
          </limit>
        </axis>
      </joint>

      <!-- Front Right Wheel -->
      <link name="front_right_wheel">
        <pose>0.35 -0.4 -0.15 -1.5708 0 0</pose>
        <inertial>
          <mass>2</mass>
          <inertia>
            <ixx>0.0225</ixx>
            <iyy>0.0225</iyy>
            <izz>0.045</izz>
          </inertia>
        </inertial>
        <collision name="front_right_wheel_collision">
          <geometry>
            <cylinder>
              <radius>0.15</radius>
              <length>0.08</length>
            </cylinder>
          </geometry>
          <surface>
            <friction>
              <ode>
                <mu>1.0</mu>
                <mu2>1.0</mu2>
              </ode>
            </friction>
          </surface>
        </collision>
        <visual name="front_right_wheel_visual">
          <geometry>
            <cylinder>
              <radius>0.15</radius>
              <length>0.08</length>
            </cylinder>
          </geometry>
          <material>
            <ambient>0.15 0.15 0.15 1</ambient>
            <diffuse>0.15 0.15 0.15 1</diffuse>
          </material>
        </visual>
      </link>

      <joint name="front_right_wheel_joint" type="revolute">
        <parent>chassis</parent>
        <child>front_right_wheel</child>
        <axis>
          <xyz>0 0 1</xyz>
          <limit>
            <lower>-1e9</lower>
            <upper>1e9</upper>
          </limit>
        </axis>
      </joint>

      <!-- Rear Left Wheel -->
      <link name="rear_left_wheel">
        <pose>-0.35 0.4 -0.15 -1.5708 0 0</pose>
        <inertial>
          <mass>2</mass>
          <inertia>
            <ixx>0.0225</ixx>
            <iyy>0.0225</iyy>
            <izz>0.045</izz>
          </inertia>
        </inertial>
        <collision name="rear_left_wheel_collision">
          <geometry>
            <cylinder>
              <radius>0.15</radius>
              <length>0.08</length>
            </cylinder>
          </geometry>
          <surface>
            <friction>
              <ode>
                <mu>1.0</mu>
                <mu2>1.0</mu2>
              </ode>
            </friction>
          </surface>
        </collision>
        <visual name="rear_left_wheel_visual">
          <geometry>
            <cylinder>
              <radius>0.15</radius>
              <length>0.08</length>
            </cylinder>
          </geometry>
          <material>
            <ambient>0.15 0.15 0.15 1</ambient>
            <diffuse>0.15 0.15 0.15 1</diffuse>
          </material>
        </visual>
      </link>

      <joint name="rear_left_wheel_joint" type="revolute">
        <parent>chassis</parent>
        <child>rear_left_wheel</child>
        <axis>
          <xyz>0 0 1</xyz>
          <limit>
            <lower>-1e9</lower>
            <upper>1e9</upper>
          </limit>
        </axis>
      </joint>

      <!-- Rear Right Wheel -->
      <link name="rear_right_wheel">
        <pose>-0.35 -0.4 -0.15 -1.5708 0 0</pose>
        <inertial>
          <mass>2</mass>
          <inertia>
            <ixx>0.0225</ixx>
            <iyy>0.0225</iyy>
            <izz>0.045</izz>
          </inertia>
        </inertial>
        <collision name="rear_right_wheel_collision">
          <geometry>
            <cylinder>
              <radius>0.15</radius>
              <length>0.08</length>
            </cylinder>
          </geometry>
          <surface>
            <friction>
              <ode>
                <mu>1.0</mu>
                <mu2>1.0</mu2>
              </ode>
            </friction>
          </surface>
        </collision>
        <visual name="rear_right_wheel_visual">
          <geometry>
            <cylinder>
              <radius>0.15</radius>
              <length>0.08</length>
            </cylinder>
          </geometry>
          <material>
            <ambient>0.15 0.15 0.15 1</ambient>
            <diffuse>0.15 0.15 0.15 1</diffuse>
          </material>
        </visual>
      </link>

      <joint name="rear_right_wheel_joint" type="revolute">
        <parent>chassis</parent>
        <child>rear_right_wheel</child>
        <axis>
          <xyz>0 0 1</xyz>
          <limit>
            <lower>-1e9</lower>
            <upper>1e9</upper>
          </limit>
        </axis>
      </joint>

      <!-- Differential Drive Plugin for Gazebo Harmonic -->
      <plugin
        filename="gz-sim-diff-drive-system"
        name="gz::sim::systems::DiffDrive">
        <left_joint>front_left_wheel_joint</left_joint>
        <left_joint>rear_left_wheel_joint</left_joint>
        <right_joint>front_right_wheel_joint</right_joint>
        <right_joint>rear_right_wheel_joint</right_joint>
        <wheel_separation>0.8</wheel_separation>
        <wheel_radius>0.15</wheel_radius>
        <odom_publish_frequency>50</odom_publish_frequency>
        <topic>cmd_vel</topic>
        <odom_topic>odom</odom_topic>
        <tf_topic>/tf</tf_topic>
        <frame_id>odom</frame_id>
        <child_frame_id>chassis</child_frame_id>
      </plugin>

      <!-- Joint State Publisher -->
      <plugin
        filename="gz-sim-joint-state-publisher-system"
        name="gz::sim::systems::JointStatePublisher">
      </plugin>

      <!-- Pose Publisher -->
      <plugin
        filename="gz-sim-pose-publisher-system"
        name="gz::sim::systems::PosePublisher">
        <publish_link_pose>true</publish_link_pose>
        <publish_collision_pose>false</publish_collision_pose>
        <publish_visual_pose>false</publish_visual_pose>
        <publish_nested_model_pose>true</publish_nested_model_pose>
      </plugin>

    </model>

  </world>
</sdf>
